Workbook

Sheet Panel Scores (2)
A3: Sum of Final_Score | B3: Column Labels
A4: Row Labels | B4: P1 | C4: P2 | D4: Grand Total
A5: AR2004 | B5: 0.2525 | C5: 1.973 | D5: 2.2255
A6: Grand Total | B6: 0.2525 | C6: 1.973 | D6: 2.2255

Sheet Panel Scores
A3: Sum of Final_Score | B3: Column Labels
A4: Row Labels | B4: P1 | C4: P2 | D4: Grand Total | E4: AVERAGE | F4: SPREAD
A5: M18 | B5: 3.999 | C5: 5.3665 | D5: 9.3655
A6: AR2001 | B6: 0.7865 | C6: 0.919 | D6: 1.7055
A7: AR2004 | B7: 0.234 | C7: 0.919 | D7: 1.153
A8: AR2005 | B8: 0.679 | C8: 0.819 | D8: 1.498
A9: AR2010 | B9: -0.125 | C9: 0.369 | D9: 0.244
A10: AR2011 | B10: 0.779 | C10: 0.919 | D10: 1.698
A11: AR2012 | B11: 0.969 | C11: 0.709 | D11: 1.678
A12: AR2013 | B12: -0.5565 | C12: 0.4665 | D12: -0.09
A13: AR2014 | B13: 0.969 | C13: 0.969 | D13: 1.938
A14: AR2015 | B14: -0.54 | C14: -0.48 | D14: -1.02
A15: AR2016 | B15: 0.969 | C15: 0.969 | D15: 1.938
A16: AR2017 | B16: 0.1575 | C16: -0.3325 | D16: -0.175
... A28: AR2012 | B28: 0.719 | C28: 0.629 | D28: 1.348
A29: AR2013 | B29: -0.15 | C29: 0.919 | D29: 0.769 | I29: Sum of Final_Score | J29: Column Labels
A30: AR2014 | B30: 0.8265 | C30: 0.769 | D30: 1.5955 | J30: P1 | K30: P2 | L30: Grand Total | M30: Average | N30: Spread
A31: AR2015 | B31: -0.3425 | C31: -0.884 | D31: -1.2265
A32: AR2016 | B32: 0.7425 | C32: 0.969 | D32: 1.7115 | I32: AR2001 | J32: 0.7865 | K32: 0.919 | L32: 1.7055 | M32: =L32/2 -> 0.85275 | N32: =IF(K32>J32,K32-J32,J32-K32) -> 0.1325
A33: AR2007 | B33: 0.434 | C33: 0.969 | D33: 1.403 | I33: AR2004 | J33: 0.234 | K33: 0.919 | L33: 1.153 | M33: =L33/2 -> 0.5765 | N33: =IF(K33>J33,K33-J33,J33-K33) -> 0.685
A34: AR2018 | B34: 0.734 | C34: 0.769 | D34: 1.503 | I34: AR2005 | J34: 0.679 | K34: 0.819 | L34: 1.498 | M34: =L34/2 -> 0.749 | N34: =IF(K34>J34,K34-J34,J34-K34) -> 0.14
A35: AR2019 | B35: -0.1025 | C35: 0.8165 | D35: 0.714 | I35: AR2010 | J35: -0.125 | K35: 0.369 | L35: 0.244 | M35: =L35/2 -> 0.122 | N35: =IF(K35>J35,K35-J35,J35-K35) -> 0.494
A36: AR2020 | B36: 0.5665 | C36: 0.134 | D36: 0.7005 | I36: AR2011 | J36: 0.779 | K36: 0.919 | L36: 1.698 | M36: =L36/2 -> 0.849 | N36: =IF(K36>J36,K36-J36,J36-K36) -> 0.14
A37: AR3006 | B37: 0.619 | C37: -0.5725 | D37: 0.0465 | I37: AR2012 | J37: 0.969 | K37: 0.709 | L37: 1.678 | M37: =L37/2 -> 0.839 | N37: =IF(K37>J37,K37-J37,J37-K37) -> 0.26
A38: AR3012 | B38: -0.799 | C38: -0.6925 | D38: -1.4915 | I38: AR2013 | J38: -0.5565 | K38: 0.4665 | L38: -0.09 | M38: =L38/2 -> -0.045 | N38: =IF(K38>J38,K38-J38,J38-K38) -> 1.023
A39: AR3013 | B39: -0.6425 | C39: -0.764 | D39: -1.4065 | I39: AR2014 | J39: 0.969 | K39: 0.969 | L39: 1.938 | M39: =L39/2 -> 0.969 | N39: =IF(K39>J39,K39-J39,J39-K39) -> 0
A40: AR3014 | B40: -0.485 | C40: -0.465 | D40: -0.95 | I40: AR2015 | J40: -0.54 | K40: -0.48 | L40: -1.02 | M40: =L40/2 -> -0.51 | N40: =IF(K40>J40,K40-J40,J40-K40) -> 0.06
A41: M19 | B41: 0.869 | C41: 9.1515 | D41: 10.0205 | I41: AR2016 | J41: 0.969 | K41: 0.969 | L41: 1.938 | M41: =L41/2 -> 0.969 | N41: =IF(K41>J41,K41-J41,J41-K41) -> 0
A42: AR2004 | B42: -0.29 | C42: 0.319 | D42: 0.029 | I42: AR2017 | J42: 0.1575 | K42: -0.3325 | L42: -0.175 | M42: =L42/2 -> -0.0875 | N42: =IF(K42>J42,K42-J42,J42-K42) -> 0.49
A43: AR2011 | B43: 0.919 | C43: 0.969 | D43: 1.888 | I43: AR3001 | J43: -0.2925 | K43: -0.6925 | L43: -0.985 | M43: =L43/2 -> -0.4925 | N43: =IF(K43>J43,K43-J43,J43-K43) -> 0.4
... A47: AR2016 | B47: 0.884 | C47: 0.919 | D47: 1.803 | I47: AR3005 | J47: -0.415 | K47: -0.066 | L47: -0.481 | M47: =L47/2 -> -0.2405 | N47: =IF(K47>J47,K47-J47,J47-K47) -> 0.349
A48: AR3004 | B48: -0.345 | C48: 0.459 | D48: 0.114
A49: AR2019 | B49: 0.519 | C49: 0.919 | D49: 1.438 | I49: AR2001 | J49: 0.634 | K49: -0.416 | L49: 0.218 | M49: =L49/2 -> 0.109 | N49: =IF(K49>J49,K49-J49,J49-K49) -> 1.05
A50: AR3006 | B50: 0.184 | C50: -0.344 | D50: -0.16 | I50: AR2004 | J50: 0.0075 | K50: -0.241 | L50: -0.2335 | M50: =L50/2 -> -0.11675 | N50: =IF(K50>J50,K50-J50,J50-K50) -> 0.2485
A51: AR2006 | B51: -0.5925 | C51: 0.409 | D51: -0.1835
A52: AR2021 | B52: -0.3175 | C52: 0.809 | D52: 0.4915
A53: AR2022 | B53: -0.564 | C53: 0.669 | D53: 0.105
A54: AR2023 | B54: 0.01 | C54: 0.26 | D54: 0.27
A55: AR2024 | B55: 0.4665 | C55: 0.819 | D55: 1.2855
A56: AR3011 | B56: 0.4265 | C56: 0.779 | D56: 1.2055
...

Sheet Panels Cores 1
A1: Semester | B1: M18
A3: Sum of Final_Score | B3: Column Labels
A4: Row Labels | B4: P1 | C4: P2 | D4: Grand Total
A5: AR2001 | B5: 0.7865 | C5: 0.919 | D5: 1.7055
A6: AR2004 | B6: 0.234 | C6: 0.919 | D6: 1.153
A7: AR2005 | B7: 0.679 | C7: 0.819 | D7: 1.498
A8: AR2010 | B8: -0.125 | C8: 0.369 | D8: 0.244
A9: AR2011 | B9: 0.779 | C9: 0.919 | D9: 1.698
A10: AR2012 | B10: 0.969 | C10: 0.709 | D10: 1.678
A11: AR2013 | B11: -0.5565 | C11: 0.4665 | D11: -0.09
A12: AR2014 | B12: 0.969 | C12: 0.969 | D12: 1.938
A13: AR2015 | B13: -0.54 | C13: -0.48 | D13: -1.02
A14: AR2016 | B14: 0.969 | C14: 0.969 | D14: 1.938
A15: AR2017 | B15: 0.1575 | C15: -0.3325 | D15: -0.175
A16: AR3001 | B16: -0.2925 | C16: -0.6925 | D16: -0.985
... A21: Grand Total | B21: 3.999 | C21: 5.3665 | D21: 9.3655

Sheet Sheet8
M24: P1 | N24: P2
L25: M18 | M25: -0.5 | N25: 0.2
L26: S19 | M26: -1 | N26: 0.5
L27: M19 | M27: 1 | N27: 1
L28: S20 | M28: 0 | N28: 1
L29: M20 | M29: 0 | N29: 0
L30: S21 | M30: 0.25 | N30: -0.25

Sheet Sheet7
B1: P1 | C1: P2
A2: AR2014 | B2: 0.969 | C2: 0.969 | D2: 1.938
A3: AR2016 | B3: 0.969 | C3: 0.969 | D3: 1.938
A4: AR2001 | B4: 0.7865 | C4: 0.919 | D4: 1.7055
A5: AR2011 | B5: 0.779 | C5: 0.919 | D5: 1.698
A6: AR2012 | B6: 0.969 | C6: 0.709 | D6: 1.678
A7: AR2005 | B7: 0.679 | C7: 0.819 | D7: 1.498
A8: AR2004 | B8: 0.234 | C8: 0.919 | D8: 1.153
A9: AR3004 | B9: 0.335 | C9: 0.669 | D9: 1.004
A10: AR3002 | B10: 0.57 | C10: -0.055 | D10: 0.515
A11: AR2010 | B11: -0.125 | C11: 0.369 | D11: 0.244
A12: AR2013 | B12: -0.5565 | C12: 0.4665 | D12: -0.09
A13: AR2017 | B13: 0.1575 | C13: -0.3325 | D13: -0.175
... A17: AR3003 | B17: -0.52 | C17: -0.735 | D17: -1.255
B24: P1 | C24: P2
B31: Panel 1 | C31: Panel 2 | D31: Conn_Start | E31: Conn_Len | F31: Conn_End | G31: Average | H31: Zero
A32: AR3004 | B32: 0.335 | C32: 0.669 | D32: =MIN(B32:C32) -> 0.335 | E32: =F32-D32 -> 0.334 | F32: =MAX(B32:C32) -> 0.669 | G32: =AVERAGE(B32:C32) -> 0.502 | H32: 0
A33: AR3002 | B33: 0.57 | C33: -0.055 | D33: =MIN(B33:C33) -> -0.055 | E33: =F33-D33 -> 0.625 | F33: =MAX(B33:C33) -> 0.57 | G33: =AVERAGE(B33:C33) -> 0.2575 | H33: 0
A34: AR3005 | B34: -0.415 | C34: -0.066 | D34: =MIN(B34:C34) -> -0.415 | E34: =F34-D34 -> 0.349 | F34: =MAX(B34:C34) -> -0.066 | G34: =AVERAGE(B34:C34) -> -0.2405 | H34: 0
A35: AR3001 | B35: -0.2925 | C35: -0.6925 | D35: =MIN(B35:C35) -> -0.6925 | E35: =F35-D35 -> 0.4 | F35: =MAX(B35:C35) -> -0.2925 | G35: =AVERAGE(B35:C35) -> -0.4925 | H35: 0
A36: AR3003 | B36: -0.52 | C36: -0.735 | D36: =MIN(B36:C36) -> -0.735 | E36: =F36-D36 -> 0.215 | F36: =MAX(B36:C36) -> -0.52 | G36: =AVERAGE(B36:C36) -> -0.6275 | H36: 0
B39: =B31 -> Panel 1 | C39: =C31 -> Panel 2 | D39: =D31 -> Conn_Start | E39: =E31 -> Conn_Len
A40: =A32 -> AR3004 | B40: =B32 -> 0.335
C41: =C32 -> 0.669
D42: =D32 -> 0.335 | E42: =E32 -> 0.334
A43: =A33 -> AR3002 | B43: =B33 -> 0.57
C44: =C33 -> -0.055
D45: =D33 -> -0.055 | E45: =E33 -> 0.625
A46: =A34 -> AR3005 | B46: =B34 -> -0.415
C47: =C34 -> -0.066
D48: =D34 -> -0.415 | E48: =E34 -> 0.349
A49: =A35 -> AR3001 | B49: =B35 -> -0.2925
C50: =C35 -> -0.6925
D51: =D35 -> -0.6925 | E51: =E35 -> 0.4
A52: =A36 -> AR3003 | B52: =B36 -> -0.52
C53: =C36 -> -0.735
D54: =B52 -> -0.52 | E54: =-E36 -> -0.215

Sheet Construct Contribution
A3: Sum of Final_Score | B3: Column Labels
A4: Row Labels | B4: P1 | C4: P2 | D4: Grand Total
A5: M18 | B5: 3.999 | C5: 5.3665 | D5: 9.3655
A6: AR2001 | B6: 0.7865 | C6: 0.919 | D6: 1.7055
A7: C1 | B7: 0.12 | C7: 0.12 | D7: 0.24
A8: C10 | B8: 0.0425 | C8: 0.085 | D8: 0.1275
A9: C11 | B9: 0.05 | C9: 0 | D9: 0.05
A10: C2 | B10: 0.064 | C10: 0.064 | D10: 0.128
A11: C3 | B11: 0.05 | C11: 0.05 | D11: 0.1
A12: C4 | B12: 0 | C12: 0.14 | D12: 0.14
A13: C6 | B13: 0.11 | C13: 0.11 | D13: 0.22
A14: C7 | B14: 0.15 | C14: 0.15 | D14: 0.3
A15: C8 | B15: 0.1 | C15: 0.1 | D15: 0.2
A16: C9 | B16: 0.1 | C16: 0.1 | D16: 0.2
... A1046: Grand Total | B1046: 24.0415 | C1046: 21.9665 | D1046: 46.008

Sheet Sheet6

Sheet Sheet3
A3: Sum of Final_Score | C3: Panel_ID
A4: Studio_Code | B4: Semester | C4: P1 | D4: P2
A5: AR2001 | B5: M18 | C5: 0.7865 | D5: 0.919
B6: S19 | C6: 0.634 | D6: -0.416
A7: AR2004 | B7: M18 | C7: 0.234 | D7: 0.919
B8: S19 | C8: 0.0075 | D8: -0.241
B9: M19 | C9: -0.29 | D9: 0.319
B10: S20 | C10: 0.234 | D10: 0.756
B11: M20 | C11: 0.067 | D11: 0.22
A12: AR2005 | B12: M18 | C12: 0.679 | D12: 0.819
B13: S19 | C13: -0.12 | D13: 0.719
B14: S20 | C14: 0.234 | D14: 0.784
A15: AR2010 | B15: M18 | C15: -0.125 | D15: 0.369
B16: S19 | C16: -0.06 | D16: 0.149
A17: AR2011 | B17: M18 | C17: 0.779 | D17: 0.919
B18: S19 | C18: 0.17 | D18: 0.969
B19: M19 | C19: 0.919 | D19: 0.969
B20: M20 | C20: 0.982 | D20: 0.537
A21: AR2012 | B21: M18 | C21: 0.969 | D21: 0.709
B22: S19 | C22: 0.719 | D22: 0.629
B23: M19 | C23: -0.28 | D23: 0.255
A24: AR2013 | B24: M18 | C24: -0.5565 | D24: 0.4665
B25: S19 | C25: -0.15 | D25: 0.919
B26: M19 | C26: -0.2525 | D26: 0.919
B27: S20 | C27: 0.424 | D27: 0.834
B28: M20 | C28: -0.025 | D28: -0.258
A29: AR2014 | B29: M18 | C29: 0.969 | D29: 0.969
B30: S19 | C30: 0.8265 | D30: 0.769
B31: M19 | C31: 0.5165 | D31: 0.969
A32: AR2015 | B32: M18 | C32: -0.54 | D32: -0.48
B33: S19 | C33: -0.3425 | D33: -0.884
A34: AR2016 | B34: M18 | C34: 0.969 | D34: 0.969
B35: S19 | C35: 0.7425 | D35: 0.969
B36: M19 | C36: 0.884 | D36: 0.919
B37: S20 | C37: 0.184 | D37: 0.214
B38: M20 | C38: 0.982 | D38: 0.332
A39: AR2017 | B39: M18 | C39: 0.1575 | D39: -0.3325
A40: AR3001 | B40: M18 | C40: -0.2925 | D40: -0.6925
A41: AR3002 | B41: M18 | C41: 0.57 | D41: -0.055
A42: AR3003 | B42: M18 | C42: -0.52 | D42: -0.735
...

Sheet Sheet10
A3: Sum of Final_Score | B3: Column Labels
A4: Row Labels | B4: C1 | C4: C10 | D4: C11 | E4: C2 | F4: C3 | G4: C4 | H4: C6 | I4: C7 | J4: C8 | K4: C9 | L4: C5 | M4: Grand Total
A5: AR2001 | B5: 0.48 | C5: 0.1275 | D5: 0 | E5: 0.256 | F5: 0.1 | G5: 0.14 | H5: 0.22 | I5: 0.3 | J5: 0.1 | K5: 0.2 | M5: 1.9235
A6: M18 | B6: 0.24 | C6: 0.1275 | D6: 0.05 | E6: 0.128 | F6: 0.1 | G6: 0.14 | H6: 0.22 | I6: 0.3 | J6: 0.2 | K6: 0.2 | M6: 1.7055
A7: P1 | B7: 0.12 | C7: 0.0425 | D7: 0.05 | E7: 0.064 | F7: 0.05 | G7: 0 | H7: 0.11 | I7: 0.15 | J7: 0.1 | K7: 0.1 | M7: 0.7865
A8: P2 | B8: 0.12 | C8: 0.085 | D8: 0 | E8: 0.064 | F8: 0.05 | G8: 0.14 | H8: 0.11 | I8: 0.15 | J8: 0.1 | K8: 0.1 | M8: 0.919
A9: S19 | B9: 0.24 | C9: 0 | D9: -0.05 | E9: 0.128 | F9: 0 | G9: 0 | H9: 0 | I9: 0 | J9: -0.1 | K9: 0 | M9: 0.218
A10: P1 | B10: 0.12 | C10: 0 | D10: 0 | E10: 0.064 | F10: 0.05 | G10: 0.14 | H10: 0.11 | I10: 0.15 | J10: 0 | K10: 0 | M10: 0.634
A11: P2 | B11: 0.12 | C11: 0 | D11: -0.05 | E11: 0.064 | F11: -0.05 | G11: -0.14 | H11: -0.11 | I11: -0.15 | J11: -0.1 | K11: 0 | M11: -0.416
A12: AR2004 | B12: 0.72 | C12: 0.2125 | D12: -0.05 | E12: 0.256 | F12: 0.35 | G12: 0.14 | H12: 0.11 | I12: 0 | J12: 0.1 | K12: 0.1 | L12: 0 | M12: 1.9385
A13: M18 | B13: 0.24 | C13: 0.085 | D13: 0 | E13: 0.128 | F13: 0.1 | G13: 0.14 | H13: 0.11 | I13: 0.15 | J13: 0.1 | K13: 0.1 | M13: 1.153
A14: P1 | B14: 0.12 | C14: 0 | D14: 0 | E14: 0.064 | F14: 0.05 | G14: 0 | H14: 0 | I14: 0 | J14: 0 | K14: 0 | M14: 0.234
A15: P2 | B15: 0.12 | C15: 0.085 | D15: 0 | E15: 0.064 | F15: 0.05 | G15: 0.14 | H15: 0.11 | I15: 0.15 | J15: 0.1 | K15: 0.1 | M15: 0.919
A16: M19 | B16: 0.12 | C16: 0.085 | D16: -0.05 | E16: 0.064 | F16: 0.1 | G16: -0.14 | H16: 0 | I16: -0.15 | J16: 0 | K16: 0 | M16: 0.029
A17: P1 | B17: 0 | C17: 0 | D17: -0.05 | E17: 0 | F17: 0.05 | G17: -0.14 | H17: 0 | I17: -0.15 | J17: 0 | K17: 0 | M17: -0.29
A18: P2 | B18: 0.12 | C18: 0.085 | D18: 0 | E18: 0.064 | F18: 0.05 | G18: 0 | H18: 0 | I18: 0 | J18: 0 | K18: 0 | M18: 0.319
A19: S19 | B19: 0.12 | C19: 0.0425 | D19: -0.05 | E19: 0.064 | F19: 0.05 | G19: 0 | H19: -0.11 | I19: -0.15 | J19: -0.1 | K19: -0.1 | M19: -0.2335
A20: P1 | B20: 0 | C20: -0.0425 | D20: 0 | E20: 0 | F20: 0.05 | G20: 0 | H20: 0 | I20: 0 | J20: 0 | K20: 0 | M20: 0.0075
A21: P2 | B21: 0.12 | C21: 0.085 | D21: -0.05 | E21: 0.064 | F21: 0 | G21: 0 | H21: -0.11 | I21: -0.15 | J21: -0.1 | K21: -0.1 | M21: -0.241
A22: S20 | B22: 0.24 | C22: 0 | D22: 0.05 | E22: 0 | F22: 0.1 | G22: 0.14 | H22: 0.11 | I22: 0.15 | J22: 0.1 | K22: 0.1 | M22: 0.99
A23: P1 | B23: 0.12 | C23: 0 | D23: 0 | E23: 0.064 | F23: 0.05 | G23: 0 | H23: 0 | I23: 0 | J23: 0 | K23: 0 | M23: 0.234
A24: P2 | B24: 0.12 | C24: 0 | D24: 0.05 | E24: -0.064 | F24: 0.05 | G24: 0.14 | H24: 0.11 | I24: 0.15 | J24: 0.1 | K24: 0.1 | M24: 0.756
A25: M20 | B25: 0 | C25: 0 | D25: 0 | E25: 0 | F25: 0 | G25: 0 | H25: 0 | I25: 0 | J25: 0 | K25: 0 | L25: 0 | M25: 0
A26: P1 | B26: 0 | C26: 0 | D26: 0 | E26: 0 | F26: 0 | G26: 0 | H26: 0 | I26: 0 | J26: 0 | K26: 0 | L26: 0 | M26: 0
A27: P2 | B27: 0 | C27: 0 | D27: 0 | E27: 0 | F27: 0 | G27: 0 | H27: 0 | I27: 0 | J27: 0 | K27: 0 | L27: 0 | M27: 0
A28: AR2005 | B28: 0.48 | C28: 0.255 | D28: 0 | E28: 0.32 | F28: 0.2 | G28: 0.42 | H28: 0.44 | I28: 0.6 | J28: 0.1 | K28: 0.3 | M28: 3.115
A29: M18 | B29: 0.24 | C29: 0.17 | D29: 0.05 | E29: 0.128 | F29: 0.05 | G29: 0.14 | H29: 0.22 | I29: 0.3 | J29: 0 | K29: 0.2 | M29: 1.498
A30: P1 | B30: 0.12 | C30: 0.085 | D30: 0.05 | E30: 0.064 | F30: 0 | G30: 0 | H30: 0.11 | I30: 0.15 | J30: 0 | K30: 0.1 | M30: 0.679
A31: P2 | B31: 0.12 | C31: 0.085 | D31: 0 | E31: 0.064 | F31: 0.05 | G31: 0.14 | H31: 0.11 | I31: 0.15 | J31: 0 | K31: 0.1 | M31: 0.819
A32: S19 | B32: 0 | C32: 0.085 | D32: 0 | E32: 0.064 | F32: 0.05 | G32: 0.14 | H32: 0.11 | I32: 0.15 | J32: 0 | K32: 0 | M32: 0.599
A33: P1 | B33: -0.12 | C33: 0 | D33: 0 | E33: 0 | F33: 0 | G33: 0 | H33: 0 | I33: 0 | J33: 0 | K33: 0 | M33: -0.12
A34: P2 | B34: 0.12 | C34: 0.085 | D34: 0 | E34: 0.064 | F34: 0.05 | G34: 0.14 | H34: 0.11 | I34: 0.15 | J34: 0 | K34: 0 | M34: 0.719
A35: S20 | B35: 0.24 | C35: 0 | D35: -0.05 | E35: 0.128 | F35: 0.1 | G35: 0.14 | H35: 0.11 | I35: 0.15 | J35: 0.1 | K35: 0.1 | M35: 1.018
A36: P1 | B36: 0.12 | C36: 0 | D36: 0 | E36: 0.064 | F36: 0.05 | G36: 0 | H36: 0 | I36: 0 | J36: 0 | K36: 0 | M36: 0.234
A37: P2 | B37: 0.12 | C37: 0 | D37: -0.05 | E37: 0.064 | F37: 0.05 | G37: 0.14 | H37: 0.11 | I37: 0.15 | J37: 0.1 | K37: 0.1 | M37: 0.784
A38: AR2006 | B38: 0.12 | C38: 0.0425 | D38: -0.05 | E38: 0.064 | F38: 0 | G38: 0 | H38: -0.11 | I38: -0.15 | J38: -0.1 | K38: 0 | M38: -0.1835
A39: M19 | B39: 0.12 | C39: 0.0425 | D39: -0.05 | E39: 0.064 | F39: 0 | G39: 0 | H39: -0.11 | I39: -0.15 | J39: -0.1 | K39: 0 | M39: -0.1835
... A232: S20 | B232: 0.24 | C232: 0 | D232: 0.1 | E232: 0.128 | F232: 0.1 | G232: 0.14 | H232: 0.11 | I232: 0.3 | J232: 0.2 | K232: 0.2 | M232: 1.518
A233: P1 | B233: 0.12 | C233: 0 | D233: 0.05 | E233: 0.064 | F233: 0.05 | G233: 0 | H233: 0 | I233: 0.15 | J233: 0.1 | K233: 0.1 | M233: 0.634 | P233: C1 | Q233: C10 | R233: C11 | S233: C2 | T233: C3 | U233: C4 | V233: C6 | W233: C7 | X233: C8 | Y233: C9 | Z233: Grand Total
A234: P2 | B234: 0.12 | C234: 0 | D234: 0.05 | E234: 0.064 | F234: 0.05 | G234: 0.14 | H234: 0.11 | I234: 0.15 | J234: 0.1 | K234: 0.1 | M234: 0.884 | N234: AR2001
...

Sheet Normalized Score
A5: 0 | B5: Semester | C5: Studio_Code | D5: Level | E5: Studio_Focus_Area | F5: Studio_Title | G5: Question_No | H5: Panel_ID | I5: Construct_ID | J5: Raw_Rating_Text | K5: Weight | L5: Confidence | M5: Final_Score | N5: Notes | Q5: raw | AB5: Weight | AC5: Confidence
A6: 2018-19 | B6: M18 | C6: AR2001 | D6: L2 | E6: Visualization and Communication | F6: The Purpose of Architecture: Exploring Design Interventions and Strategies | G6: 1 | H6: P1 | I6: C1 | J6: 1 | K6: =AB6/COUNTIFS($B:$B,$B6,$C:$C,$C6,$H:$H,$H6,$I:$I,$I6) -> 0.12 | L6: =AC6 -> 1 | M6: =J6*K6*L6 -> 0.12 | O6: =tScores[[#This Row],[Raw_Rating_Text]]+J8+J10+J12+J14+J16+J18+J20+J22+J24+J26 -> 9 | P6: =K6+K8+K10+K12+K14+K16+K18+K20+K22+K24+K26 -> 1 | Q6: =L6+L8+L10+L12+L14+L16+L18+L20+L22+L24+L26 -> 10.5 | R6: =M6+M8+M10+M12+M14+M16+M18+M20+M22+M24+M26 -> 0.7865 | AA6: =AB6/COUNTIFS($B:$B,$B6,$C:$C,$C6,$H:$H,$H6,$I:$I,$I6) -> 0.12 | AB6: =VLOOKUP(I6,'Weights and Confidence'!$D$16:$AC$26,3,FALSE) -> 0.12 | AC6: =VLOOKUP(I6,'Weights and Confidence'!$D$16:$AC$26,4,FALSE) -> 1
A7: 2018-19 | B7: M18 | C7: AR2001 | D7: L2 | E7: Visualization and Communication | F7: The Purpose of Architecture: Exploring Design Interventions and Strategies | G7: 1 | H7: P2 | I7: C1 | J7: 1 | K7: =AB7/COUNTIFS($B:$B,$B7,$C:$C,$C7,$H:$H,$H7,$I:$I,$I7) -> 0.12 | L7: =AC7 -> 1 | M7: =J7*K7*L7 -> 0.12 | O7: =tScores[[#This Row],[Raw_Rating_Text]]+J9+J11+J13+J15+J17+J19+J21+J23+J25+J27 -> 10 | P7: =K7+K9+K11+K13+K15+K17+K19+K21+K23+K25+K27 -> 1 | Q7: =L7+L9+L11+L13+L15+L17+L19+L21+L23+L25+L27 -> 10.5 | R7: =M7+M9+M11+M13+M15+M17+M19+M21+M23+M25+M27 -> 0.919 | AA7: =AB7/COUNTIFS($B:$B,$B7,$C:$C,$C7,$H:$H,$H7,$I:$I,$I7) -> 0.12 | AB7: =VLOOKUP(I7,'Weights and Confidence'!$D$16:$AC$26,3,FALSE) -> 0.12 | AC7: =VLOOKUP(I7,'Weights and Confidence'!$D$16:$AC$26,4,FALSE) -> 1
A8: 2018-19 | B8: M18 | C8: AR2001 | D8: L2 | E8: Visualization and Communication | F8: The Purpose of Architecture: Exploring Design Interventions and Strategies | G8: 2 | H8: P1 | I8: C2 | J8: 1 | K8: =AB8/COUNTIFS($B:$B,$B8,$C:$C,$C8,$H:$H,$H8,$I:$I,$I8) -> 0.08 | L8: =AC8 -> 0.8 | M8: =J8*K8*L8 -> 0.064 | AA8: =AB8/COUNTIFS($B:$B,$B8,$C:$C,$C8,$H:$H,$H8,$I:$I,$I8) -> 0.08 | AB8: =VLOOKUP(I8,'Weights and Confidence'!$D$16:$AC$26,3,FALSE) -> 0.08 | AC8: =VLOOKUP(I8,'Weights and Confidence'!$D$16:$AC$26,4,FALSE) -> 0.8
A9: 2018-19 | B9: M18 | C9: AR2001 | D9: L2 | E9: Visualization and Communication | F9: The Purpose of Architecture: Exploring Design Interventions and Strategies | G9: 2 | H9: P2 | I9: C2 | J9: 1 | K9: =AB9/COUNTIFS($B:$B,$B9,$C:$C,$C9,$H:$H,$H9,$I:$I,$I9) -> 0.08 | L9: =AC9 -> 0.8 | M9: =J9*K9*L9 -> 0.064 | AA9: =AB9/COUNTIFS($B:$B,$B9,$C:$C,$C9,$H:$H,$H9,$I:$I,$I9) -> 0.08 | AB9: =VLOOKUP(I9,'Weights and Confidence'!$D$16:$AC$26,3,FALSE) -> 0.08 | AC9: =VLOOKUP(I9,'Weights and Confidence'!$D$16:$AC$26,4,FALSE) -> 0.8
A10: 2018-19 | B10: M18 | C10: AR2001 | D10: L2 | E10: Visualization and Communication | F10: The Purpose of Architecture: Exploring Design Interventions and Strategies | G10: 3 | H10: P1 | I10: C3 | J10: 1 | K10: =AB10/COUNTIFS($B:$B,$B10,$C:$C,$C10,$H:$H,$H10,$I:$I,$I10) -> 0.05 | L10: =AC10 -> 1 | M10: =J10*K10*L10 -> 0.05 | AA10: =AB10/COUNTIFS($B:$B,$B10,$C:$C,$C10,$H:$H,$H10,$I:$I,$I10) -> 0.05 | AB10: =VLOOKUP(I10,'Weights and Confidence'!$D$16:$AC$26,3,FALSE) -> 0.05 | AC10: =VLOOKUP(I10,'Weights and Confidence'!$D$16:$AC$26,4,FALSE) -> 1
A11: 2018-19 | B11: M18 | C11: AR2001 | D11: L2 | E11: Visualization and Communication | F11: The Purpose of Architecture: Exploring Design Interventions and Strategies | G11: 3 | H11: P2 | I11: C3 | J11: 1 | K11: =AB11/COUNTIFS($B:$B,$B11,$C:$C,$C11,$H:$H,$H11,$I:$I,$I11) -> 0.05 | L11: =AC11 -> 1 | M11: =J11*K11*L11 -> 0.05 | AA11: =AB11/COUNTIFS($B:$B,$B11,$C:$C,$C11,$H:$H,$H11,$I:$I,$I11) -> 0.05 | AB11: =VLOOKUP(I11,'Weights and Confidence'!$D$16:$AC$26,3,FALSE) -> 0.05 | AC11: =VLOOKUP(I11,'Weights and Confidence'!$D$16:$AC$26,4,FALSE) -> 1
A12: 2018-19 | B12: M18 | C12: AR2001 | D12: L2 | E12: Visualization and Communication | F12: The Purpose of Architecture: Exploring Design Interventions and Strategies | G12: 4 | H12: P1 | I12: C4 | J12: 0 | K12: =AB12/COUNTIFS($B:$B,$B12,$C:$C,$C12,$H:$H,$H12,$I:$I,$I12) -> 0.14 | L12: =AC12 -> 1 | M12: =J12*K12*L12 -> 0 | AA12: =AB12/COUNTIFS($B:$B,$B12,$C:$C,$C12,$H:$H,$H12,$I:$I,$I12) -> 0.14 | AB12: =VLOOKUP(I12,'Weights and Confidence'!$D$16:$AC$26,3,FALSE) -> 0.14 | AC12: =VLOOKUP(I12,'Weights and Confidence'!$D$16:$AC$26,4,FALSE) -> 1
A13: 2018-19 | B13: M18 | C13: AR2001 | D13: L2 | E13: Visualization and Communication | F13: The Purpose of Architecture: Exploring Design Interventions and Strategies | G13: 4 | H13: P2 | I13: C4 | J13: 1 | K13: =AB13/COUNTIFS($B:$B,$B13,$C:$C,$C13,$H:$H,$H13,$I:$I,$I13) -> 0.14 | L13: =AC13 -> 1 | M13: =J13*K13*L13 -> 0.14 | AA13: =AB13/COUNTIFS($B:$B,$B13,$C:$C,$C13,$H:$H,$H13,$I:$I,$I13) -> 0.14 | AB13: =VLOOKUP(I13,'Weights and Confidence'!$D$16:$AC$26,3,FALSE) -> 0.14 | AC13: =VLOOKUP(I13,'Weights and Confidence'!$D$16:$AC$26,4,FALSE) -> 1
A14: 2018-19 | B14: M18 | C14: AR2001 | D14: L2 | E14: Visualization and Communication | F14: The Purpose of Architecture: Exploring Design Interventions and Strategies | G14: 5 | H14: P1 | I14: C6 | J14: 1 | K14: =AB14/COUNTIFS($B:$B,$B14,$C:$C,$C14,$H:$H,$H14,$I:$I,$I14) -> 0.11 | L14: =AC14 -> 1 | M14: =J14*K14*L14 -> 0.11 | AA14: =AB14/COUNTIFS($B:$B,$B14,$C:$C,$C14,$H:$H,$H14,$I:$I,$I14) -> 0.11 | AB14: =VLOOKUP(I14,'Weights and Confidence'!$D$16:$AC$26,3,FALSE) -> 0.11 | AC14: =VLOOKUP(I14,'Weights and Confidence'!$D$16:$AC$26,4,FALSE) -> 1
A15: 2018-19 | B15: M18 | C15: AR2001 | D15: L2 | E15: Visualization and Communication | F15: The Purpose of Architecture: Exploring Design Interventions and Strategies | G15: 5 | H15: P2 | I15: C6 | J15: 1 | K15: =AB15/COUNTIFS($B:$B,$B15,$C:$C,$C15,$H:$H,$H15,$I:$I,$I15) -> 0.11 | L15: =AC15 -> 1 | M15: =J15*K15*L15 -> 0.11 | AA15: =AB15/COUNTIFS($B:$B,$B15,$C:$C,$C15,$H:$H,$H15,$I:$I,$I15) -> 0.11 | AB15: =VLOOKUP(I15,'Weights and Confidence'!$D$16:$AC$26,3,FALSE) -> 0.11 | AC15: =VLOOKUP(I15,'Weights and Confidence'!$D$16:$AC$26,4,FALSE) -> 1
A16: 2018-19 | B16: M18 | C16: AR2001 | D16: L2 | E16: Visualization and Communication | F16: The Purpose of Architecture: Exploring Design Interventions and Strategies | G16: 6 | H16: P1 | I16: C7 | J16: 1 | K16: =AB16/COUNTIFS($B:$B,$B16,$C:$C,$C16,$H:$H,$H16,$I:$I,$I16) -> 0.15 | L16: =AC16 -> 1 | M16: =J16*K16*L16 -> 0.15 | AA16: =AB16/COUNTIFS($B:$B,$B16,$C:$C,$C16,$H:$H,$H16,$I:$I,$I16) -> 0.15 | AB16: =VLOOKUP(I16,'Weights and Confidence'!$D$16:$AC$26,3,FALSE) -> 0.15 | AC16: =VLOOKUP(I16,'Weights and Confidence'!$D$16:$AC$26,4,FALSE) -> 1
A17: 2018-19 | B17: M18 | C17: AR2001 | D17: L2 | E17: Visualization and Communication | F17: The Purpose of Architecture: Exploring Design Interventions and Strategies | G17: 6 | H17: P2 | I17: C7 | J17: 1 | K17: =AB17/COUNTIFS($B:$B,$B17,$C:$C,$C17,$H:$H,$H17,$I:$I,$I17) -> 0.15 | L17: =AC17 -> 1 | M17: =J17*K17*L17 -> 0.15 | AA17: =AB17/COUNTIFS($B:$B,$B17,$C:$C,$C17,$H:$H,$H17,$I:$I,$I17) -> 0.15 | AB17: =VLOOKUP(I17,'Weights and Confidence'!$D$16:$AC$26,3,FALSE) -> 0.15 | AC17: =VLOOKUP(I17,'Weights and Confidence'!$D$16:$AC$26,4,FALSE) -> 1
A18: 2018-19 | B18: M18 | C18: AR2001 | D18: L2 | E18: Visualization and Communication | F18: The Purpose of Architecture: Exploring Design Interventions and Strategies | G18: 7 | H18: P1 | I18: C8 | J18: 1 | K18: =AB18/COUNTIFS($B:$B,$B18,$C:$C,$C18,$H:$H,$H18,$I:$I,$I18) -> 0.1 | L18: =AC18 -> 1 | M18: =J18*K18*L18 -> 0.1 | AA18: =AB18/COUNTIFS($B:$B,$B18,$C:$C,$C18,$H:$H,$H18,$I:$I,$I18) -> 0.1 | AB18: =VLOOKUP(I18,'Weights and Confidence'!$D$16:$AC$26,3,FALSE) -> 0.1 | AC18: =VLOOKUP(I18,'Weights and Confidence'!$D$16:$AC$26,4,FALSE) -> 1
A19: 2018-19 | B19: M18 | C19: AR2001 | D19: L2 | E19: Visualization and Communication | F19: The Purpose of Architecture: Exploring Design Interventions and Strategies | G19: 7 | H19: P2 | I19: C8 | J19: 1 | K19: =AB19/COUNTIFS($B:$B,$B19,$C:$C,$C19,$H:$H,$H19,$I:$I,$I19) -> 0.1 | L19: =AC19 -> 1 | M19: =J19*K19*L19 -> 0.1 | AA19: =AB19/COUNTIFS($B:$B,$B19,$C:$C,$C19,$H:$H,$H19,$I:$I,$I19) -> 0.1 | AB19: =VLOOKUP(I19,'Weights and Confidence'!$D$16:$AC$26,3,FALSE) -> 0.1 | AC19: =VLOOKUP(I19,'Weights and Confidence'!$D$16:$AC$26,4,FALSE) -> 1
... A27: 2018-19 | B27: M18 | C27: AR2001 | D27: L2 | E27: Visualization and Communication | F27: The Purpose of Architecture: Exploring Design Interventions and Strategies | G27: 11 | H27: P2 | I27: C11 | J27: 0 | K27: =AB27/COUNTIFS($B:$B,$B27,$C:$C,$C27,$H:$H,$H27,$I:$I,$I27) -> 0.05 | L27: =AC27 -> 1 | M27: =J27*K27*L27 -> 0 | AA27: =AB27/COUNTIFS($B:$B,$B27,$C:$C,$C27,$H:$H,$H27,$I:$I,$I27) -> 0.05 | AB27: =VLOOKUP(I27,'Weights and Confidence'!$D$16:$AC$26,3,FALSE) -> 0.05 | AC27: =VLOOKUP(I27,'Weights and Confidence'!$D$16:$AC$26,4,FALSE) -> 1
A28: 2018-19 | B28: M18 | C28: AR2004 | D28: L2 | E28: Constructing and Specifying | F28: Strange Details | G28: 1 | H28: P1 | I28: C1 | J28: 1 | K28: =AB28/COUNTIFS($B:$B,$B28,$C:$C,$C28,$H:$H,$H28,$I:$I,$I28) -> 0.12 | L28: =AC28 -> 1 | M28: =J28*K28*L28 -> 0.12 | O28: =tScores[[#This Row],[Raw_Rating_Text]]+J30+J32+J34+J36+J38+J40+J42+J44+J46+J48 -> 3 | R28: =tScores[[#This Row],[Final_Score]]+M30+M32+M34+M36+M38+M40+M42+M44+M46+M48 -> 0.234 | AA28: =AB28/COUNTIFS($B:$B,$B28,$C:$C,$C28,$H:$H,$H28,$I:$I,$I28) -> 0.12 | AB28: =VLOOKUP(I28,'Weights and Confidence'!$D$16:$AC$26,3,FALSE) -> 0.12 | AC28: =VLOOKUP(I28,'Weights and Confidence'!$D$16:$AC$26,4,FALSE) -> 1
A29: 2018-19 | B29: M18 | C29: AR2004 | D29: L2 | E29: Constructing and Specifying | F29: Strange Details | G29: 1 | H29: P2 | I29: C1 | J29: 1 | K29: =AB29/COUNTIFS($B:$B,$B29,$C:$C,$C29,$H:$H,$H29,$I:$I,$I29) -> 0.12 | L29: =AC29 -> 1 | M29: =J29*K29*L29 -> 0.12 | O29: =tScores[[#This Row],[Raw_Rating_Text]]+J31+J33+J35+J37+J39+J41+J43+J45+J47+J49 -> 10 | R29: =tScores[[#This Row],[Final_Score]]+M31+M33+M35+M37+M39+M41+M43+M45+M47+M49 -> 0.919 | AA29: =AB29/COUNTIFS($B:$B,$B29,$C:$C,$C29,$H:$H,$H29,$I:$I,$I29) -> 0.12 | AB29: =VLOOKUP(I29,'Weights and Confidence'!$D$16:$AC$26,3,FALSE) -> 0.12 | AC29: =VLOOKUP(I29,'Weights and Confidence'!$D$16:$AC$26,4,FALSE) -> 1
A30: 2018-19 | B30: M18 | C30: AR2004 | D30: L2 | E30: Constructing and Specifying | F30: Strange Details | G30: 2 | H30: P1 | I30: C2 | J30: 1 | K30: =AB30/COUNTIFS($B:$B,$B30,$C:$C,$C30,$H:$H,$H30,$I:$I,$I30) -> 0.08 | L30: =AC30 -> 0.8 | M30: =J30*K30*L30 -> 0.064 | AA30: =AB30/COUNTIFS($B:$B,$B30,$C:$C,$C30,$H:$H,$H30,$I:$I,$I30) -> 0.08 | AB30: =VLOOKUP(I30,'Weights and Confidence'!$D$16:$AC$26,3,FALSE) -> 0.08 | AC30: =VLOOKUP(I30,'Weights and Confidence'!$D$16:$AC$26,4,FALSE) -> 0.8
A31: 2018-19 | B31: M18 | C31: AR2004 | D31: L2 | E31: Constructing and Specifying | F31: Strange Details | G31: 2 | H31: P2 | I31: C2 | J31: 1 | K31: =AB31/COUNTIFS($B:$B,$B31,$C:$C,$C31,$H:$H,$H31,$I:$I,$I31) -> 0.08 | L31: =AC31 -> 0.8 | M31: =J31*K31*L31 -> 0.064 | AA31: =AB31/COUNTIFS($B:$B,$B31,$C:$C,$C31,$H:$H,$H31,$I:$I,$I31) -> 0.08 | AB31: =VLOOKUP(I31,'Weights and Confidence'!$D$16:$AC$26,3,FALSE) -> 0.08 | AC31: =VLOOKUP(I31,'Weights and Confidence'!$D$16:$AC$26,4,FALSE) -> 0.8
A32: 2018-19 | B32: M18 | C32: AR2004 | D32: L2 | E32: Constructing and Specifying | F32: Strange Details | G32: 3 | H32: P1 | I32: C3 | J32: 1 | K32: =AB32/COUNTIFS($B:$B,$B32,$C:$C,$C32,$H:$H,$H32,$I:$I,$I32) -> 0.05 | L32: =AC32 -> 1 | M32: =J32*K32*L32 -> 0.05 | AA32: =AB32/COUNTIFS($B:$B,$B32,$C:$C,$C32,$H:$H,$H32,$I:$I,$I32) -> 0.05 | AB32: =VLOOKUP(I32,'Weights and Confidence'!$D$16:$AC$26,3,FALSE) -> 0.05 | AC32: =VLOOKUP(I32,'Weights and Confidence'!$D$16:$AC$26,4,FALSE) -> 1
A33: 2018-19 | B33: M18 | C33: AR2004 | D33: L2 | E33: Constructing and Specifying | F33: Strange Details | G33: 3 | H33: P2 | I33: C3 | J33: 1 | K33: =AB33/COUNTIFS($B:$B,$B33,$C:$C,$C33,$H:$H,$H33,$I:$I,$I33) -> 0.05 | L33: =AC33 -> 1 | M33: =J33*K33*L33 -> 0.05 | AA33: =AB33/COUNTIFS($B:$B,$B33,$C:$C,$C33,$H:$H,$H33,$I:$I,$I33) -> 0.05 | AB33: =VLOOKUP(I33,'Weights and Confidence'!$D$16:$AC$26,3,FALSE) -> 0.05 | AC33: =VLOOKUP(I33,'Weights and Confidence'!$D$16:$AC$26,4,FALSE) -> 1
A34: 2018-19 | B34: M18 | C34: AR2004 | D34: L2 | E34: Constructing and Specifying | F34: Strange Details | G34: 4 | H34: P1 | I34: C4 | J34: 0 | K34: =AB34/COUNTIFS($B:$B,$B34,$C:$C,$C34,$H:$H,$H34,$I:$I,$I34) -> 0.14 | L34: =AC34 -> 1 | M34: =J34*K34*L34 -> 0 | AA34: =AB34/COUNTIFS($B:$B,$B34,$C:$C,$C34,$H:$H,$H34,$I:$I,$I34) -> 0.14 | AB34: =VLOOKUP(I34,'Weights and Confidence'!$D$16:$AC$26,3,FALSE) -> 0.14 | AC34: =VLOOKUP(I34,'Weights and Confidence'!$D$16:$AC$26,4,FALSE) -> 1
A35: 2018-19 | B35: M18 | C35: AR2004 | D35: L2 | E35: Constructing and Specifying | F35: Strange Details | G35: 4 | H35: P2 | I35: C4 | J35: 1 | K35: =AB35/COUNTIFS($B:$B,$B35,$C:$C,$C35,$H:$H,$H35,$I:$I,$I35) -> 0.14 | L35: =AC35 -> 1 | M35: =J35*K35*L35 -> 0.14 | AA35: =AB35/COUNTIFS($B:$B,$B35,$C:$C,$C35,$H:$H,$H35,$I:$I,$I35) -> 0.14 | AB35: =VLOOKUP(I35,'Weights and Confidence'!$D$16:$AC$26,3,FALSE) -> 0.14 | AC35: =VLOOKUP(I35,'Weights and Confidence'!$D$16:$AC$26,4,FALSE) -> 1
A36: 2018-19 | B36: M18 | C36: AR2004 | D36: L2 | E36: Constructing and Specifying | F36: Strange Details | G36: 5 | H36: P1 | I36: C6 | J36: 0 | K36: =AB36/COUNTIFS($B:$B,$B36,$C:$C,$C36,$H:$H,$H36,$I:$I,$I36) -> 0.11 | L36: =AC36 -> 1 | M36: =J36*K36*L36 -> 0 | AA36: =AB36/COUNTIFS($B:$B,$B36,$C:$C,$C36,$H:$H,$H36,$I:$I,$I36) -> 0.11 | AB36: =VLOOKUP(I36,'Weights and Confidence'!$D$16:$AC$26,3,FALSE) -> 0.11 | AC36: =VLOOKUP(I36,'Weights and Confidence'!$D$16:$AC$26,4,FALSE) -> 1
A37: 2018-19 | B37: M18 | C37: AR2004 | D37: L2 | E37: Constructing and Specifying | F37: Strange Details | G37: 5 | H37: P2 | I37: C6 | J37: 1 | K37: =AB37/COUNTIFS($B:$B,$B37,$C:$C,$C37,$H:$H,$H37,$I:$I,$I37) -> 0.11 | L37: =AC37 -> 1 | M37: =J37*K37*L37 -> 0.11 | AA37: =AB37/COUNTIFS($B:$B,$B37,$C:$C,$C37,$H:$H,$H37,$I:$I,$I37) -> 0.11 | AB37: =VLOOKUP(I37,'Weights and Confidence'!$D$16:$AC$26,3,FALSE) -> 0.11 | AC37: =VLOOKUP(I37,'Weights and Confidence'!$D$16:$AC$26,4,FALSE) -> 1
A38: 2018-19 | B38: M18 | C38: AR2004 | D38: L2 | E38: Constructing and Specifying | F38: Strange Details | G38: 6 | H38: P1 | I38: C7 | J38: 0 | K38: =AB38/COUNTIFS($B:$B,$B38,$C:$C,$C38,$H:$H,$H38,$I:$I,$I38) -> 0.15 | L38: =AC38 -> 1 | M38: =J38*K38*L38 -> 0 | AA38: =AB38/COUNTIFS($B:$B,$B38,$C:$C,$C38,$H:$H,$H38,$I:$I,$I38) -> 0.15 | AB38: =VLOOKUP(I38,'Weights and Confidence'!$D$16:$AC$26,3,FALSE) -> 0.15 | AC38: =VLOOKUP(I38,'Weights and Confidence'!$D$16:$AC$26,4,FALSE) -> 1
A39: 2018-19 | B39: M18 | C39: AR2004 | D39: L2 | E39: Constructing and Specifying | F39: Strange Details | G39: 6 | H39: P2 | I39: C7 | J39: 1 | K39: =AB39/COUNTIFS($B:$B,$B39,$C:$C,$C39,$H:$H,$H39,$I:$I,$I39) -> 0.15 | L39: =AC39 -> 1 | M39: =J39*K39*L39 -> 0.15 | AA39: =AB39/COUNTIFS($B:$B,$B39,$C:$C,$C39,$H:$H,$H39,$I:$I,$I39) -> 0.15 | AB39: =VLOOKUP(I39,'Weights and Confidence'!$D$16:$AC$26,3,FALSE) -> 0.15 | AC39: =VLOOKUP(I39,'Weights and Confidence'!$D$16:$AC$26,4,FALSE) -> 1
A40: 2018-19 | B40: M18 | C40: AR2004 | D40: L2 | E40: Constructing and Specifying | F40: Strange Details | G40: 7 | H40: P1 | I40: C8 | J40: 0 | K40: =AB40/COUNTIFS($B:$B,$B40,$C:$C,$C40,$H:$H,$H40,$I:$I,$I40) -> 0.1 | L40: =AC40 -> 1 | M40: =J40*K40*L40 -> 0 | AA40: =AB40/COUNTIFS($B:$B,$B40,$C:$C,$C40,$H:$H,$H40,$I:$I,$I40) -> 0.1 | AB40: =VLOOKUP(I40,'Weights and Confidence'!$D$16:$AC$26,3,FALSE) -> 0.1 | AC40: =VLOOKUP(I40,'Weights and Confidence'!$D$16:$AC$26,4,FALSE) -> 1
A41: 2018-19 | B41: M18 | C41: AR2004 | D41: L2 | E41: Constructing and Specifying | F41: Strange Details | G41: 7 | H41: P2 | I41: C8 | J41: 1 | K41: =AB41/COUNTIFS($B:$B,$B41,$C:$C,$C41,$H:$H,$H41,$I:$I,$I41) -> 0.1 | L41: =AC41 -> 1 | M41: =J41*K41*L41 -> 0.1 | AA41: =AB41/COUNTIFS($B:$B,$B41,$C:$C,$C41,$H:$H,$H41,$I:$I,$I41) -> 0.1 | AB41: =VLOOKUP(I41,'Weights and Confidence'!$D$16:$AC$26,3,FALSE) -> 0.1 | AC41: =VLOOKUP(I41,'Weights and Confidence'!$D$16:$AC$26,4,FALSE) -> 1
... A49: 2018-19 | B49: M18 | C49: AR2004 | D49: L2 | E49: Constructing and Specifying | F49: Strange Details | G49: 11 | H49: P2 | I49: C11 | J49: 0 | K49: =AB49/COUNTIFS($B:$B,$B49,$C:$C,$C49,$H:$H,$H49,$I:$I,$I49) -> 0.05 | L49: =AC49 -> 1 | M49: =J49*K49*L49 -> 0 | AA49: =AB49/COUNTIFS($B:$B,$B49,$C:$C,$C49,$H:$H,$H49,$I:$I,$I49) -> 0.05 | AB49: =VLOOKUP(I49,'Weights and Confidence'!$D$16:$AC$26,3,FALSE) -> 0.05 | AC49: =VLOOKUP(I49,'Weights and Confidence'!$D$16:$AC$26,4,FALSE) -> 1
A50: 2018-19 | B50: M18 | C50: AR2005 | D50: L2 | E50: Spatial Planning and Organization | F50: Of Immediate and Afar | G50: 1 | H50: P1 | I50: C1 | J50: 1 | K50: =AB50/COUNTIFS($B:$B,$B50,$C:$C,$C50,$H:$H,$H50,$I:$I,$I50) -> 0.12 | L50: =AC50 -> 1 | M50: =J50*K50*L50 -> 0.12 | O50: =tScores[[#This Row],[Raw_Rating_Text]]+J52+J54+J56+J58+J60+J62+J64+J66+J68+J70 -> 8 | P50: ='Normalized Score'!$M50+M52+M54+M56+M58+M60+M62+M64+M66+M68+M70 -> 0.679 | AA50: =AB50/COUNTIFS($B:$B,$B50,$C:$C,$C50,$H:$H,$H50,$I:$I,$I50) -> 0.12 | AB50: =VLOOKUP(I50,'Weights and Confidence'!$D$16:$AC$26,3,FALSE) -> 0.12 | AC50: =VLOOKUP(I50,'Weights and Confidence'!$D$16:$AC$26,4,FALSE) -> 1
A51: 2018-19 | B51: M18 | C51: AR2005 | D51: L2 | E51: Spatial Planning and Organization | F51: Of Immediate and Afar | G51: 1 | H51: P2 | I51: C1 | J51: 1 | K51: =AB51/COUNTIFS($B:$B,$B51,$C:$C,$C51,$H:$H,$H51,$I:$I,$I51) -> 0.12 | L51: =AC51 -> 1 | M51: =J51*K51*L51 -> 0.12 | O51: =tScores[[#This Row],[Raw_Rating_Text]]+J53+J55+J57+J59+J61+J63+J65+J67+J69+J71 -> 9 | AA51: =AB51/COUNTIFS($B:$B,$B51,$C:$C,$C51,$H:$H,$H51,$I:$I,$I51) -> 0.12 | AB51: =VLOOKUP(I51,'Weights and Confidence'!$D$16:$AC$26,3,FALSE) -> 0.12 | AC51: =VLOOKUP(I51,'Weights and Confidence'!$D$16:$AC$26,4,FALSE) -> 1
A52: 2018-19 | B52: M18 | C52: AR2005 | D52: L2 | E52: Spatial Planning and Organization | F52: Of Immediate and Afar | G52: 2 | H52: P1 | I52: C2 | J52: 1 | K52: =AB52/COUNTIFS($B:$B,$B52,$C:$C,$C52,$H:$H,$H52,$I:$I,$I52) -> 0.08 | L52: =AC52 -> 0.8 | M52: =J52*K52*L52 -> 0.064 | AA52: =AB52/COUNTIFS($B:$B,$B52,$C:$C,$C52,$H:$H,$H52,$I:$I,$I52) -> 0.08 | AB52: =VLOOKUP(I52,'Weights and Confidence'!$D$16:$AC$26,3,FALSE) -> 0.08 | AC52: =VLOOKUP(I52,'Weights and Confidence'!$D$16:$AC$26,4,FALSE) -> 0.8
A53: 2018-19 | B53: M18 | C53: AR2005 | D53: L2 | E53: Spatial Planning and Organization | F53: Of Immediate and Afar | G53: 2 | H53: P2 | I53: C2 | J53: 1 | K53: =AB53/COUNTIFS($B:$B,$B53,$C:$C,$C53,$H:$H,$H53,$I:$I,$I53) -> 0.08 | L53: =AC53 -> 0.8 | M53: =J53*K53*L53 -> 0.064 | AA53: =AB53/COUNTIFS($B:$B,$B53,$C:$C,$C53,$H:$H,$H53,$I:$I,$I53) -> 0.08 | AB53: =VLOOKUP(I53,'Weights and Confidence'!$D$16:$AC$26,3,FALSE) -> 0.08 | AC53: =VLOOKUP(I53,'Weights and Confidence'!$D$16:$AC$26,4,FALSE) -> 0.8
A54: 2018-19 | B54: M18 | C54: AR2005 | D54: L2 | E54: Spatial Planning and Organization | F54: Of Immediate and Afar | G54: 3 | H54: P1 | I54: C3 | J54: 0 | K54: =AB54/COUNTIFS($B:$B,$B54,$C:$C,$C54,$H:$H,$H54,$I:$I,$I54) -> 0.05 | L54: =AC54 -> 1 | M54: =J54*K54*L54 -> 0 | AA54: =AB54/COUNTIFS($B:$B,$B54,$C:$C,$C54,$H:$H,$H54,$I:$I,$I54) -> 0.05 | AB54: =VLOOKUP(I54,'Weights and Confidence'!$D$16:$AC$26,3,FALSE) -> 0.05 | AC54: =VLOOKUP(I54,'Weights and Confidence'!$D$16:$AC$26,4,FALSE) -> 1
A55: 2018-19 | B55: M18 | C55: AR2005 | D55: L2 | E55: Spatial Planning and Organization | F55: Of Immediate and Afar | G55: 3 | H55: P2 | I55: C3 | J55: 1 | K55: =AB55/COUNTIFS($B:$B,$B55,$C:$C,$C55,$H:$H,$H55,$I:$I,$I55) -> 0.05 | L55: =AC55 -> 1 | M55: =J55*K55*L55 -> 0.05 | AA55: =AB55/COUNTIFS($B:$B,$B55,$C:$C,$C55,$H:$H,$H55,$I:$I,$I55) -> 0.05 | AB55: =VLOOKUP(I55,'Weights and Confidence'!$D$16:$AC$26,3,FALSE) -> 0.05 | AC55: =VLOOKUP(I55,'Weights and Confidence'!$D$16:$AC$26,4,FALSE) -> 1
A56: 2018-19 | B56: M18 | C56: AR2005 | D56: L2 | E56: Spatial Planning and Organization | F56: Of Immediate and Afar | G56: 4 | H56: P1 | I56: C4 | J56: 0 | K56: =AB56/COUNTIFS($B:$B,$B56,$C:$C,$C56,$H:$H,$H56,$I:$I,$I56) -> 0.14 | L56: =AC56 -> 1 | M56: =J56*K56*L56 -> 0 | AA56: =AB56/COUNTIFS($B:$B,$B56,$C:$C,$C56,$H:$H,$H56,$I:$I,$I56) -> 0.14 | AB56: =VLOOKUP(I56,'Weights and Confidence'!$D$16:$AC$26,3,FALSE) -> 0.14 | AC56: =VLOOKUP(I56,'Weights and Confidence'!$D$16:$AC$26,4,FALSE) -> 1
A57: 2018-19 | B57: M18 | C57: AR2005 | D57: L2 | E57: Spatial Planning and Organization | F57: Of Immediate and Afar | G57: 4 | H57: P2 | I57: C4 | J57: 1 | K57: =AB57/COUNTIFS($B:$B,$B57,$C:$C,$C57,$H:$H,$H57,$I:$I,$I57) -> 0.14 | L57: =AC57 -> 1 | M57: =J57*K57*L57 -> 0.14 | AA57: =AB57/COUNTIFS($B:$B,$B57,$C:$C,$C57,$H:$H,$H57,$I:$I,$I57) -> 0.14 | AB57: =VLOOKUP(I57,'Weights and Confidence'!$D$16:$AC$26,3,FALSE) -> 0.14 | AC57: =VLOOKUP(I57,'Weights and Confidence'!$D$16:$AC$26,4,FALSE) -> 1
A58: 2018-19 | B58: M18 | C58: AR2005 | D58: L2 | E58: Spatial Planning and Organization | F58: Of Immediate and Afar | G58: 5 | H58: P1 | I58: C6 | J58: 1 | K58: =AB58/COUNTIFS($B:$B,$B58,$C:$C,$C58,$H:$H,$H58,$I:$I,$I58) -> 0.11 | L58: =AC58 -> 1 | M58: =J58*K58*L58 -> 0.11 | AA58: =AB58/COUNTIFS($B:$B,$B58,$C:$C,$C58,$H:$H,$H58,$I:$I,$I58) -> 0.11 | AB58: =VLOOKUP(I58,'Weights and Confidence'!$D$16:$AC$26,3,FALSE) -> 0.11 | AC58: =VLOOKUP(I58,'Weights and Confidence'!$D$16:$AC$26,4,FALSE) -> 1
...

Sheet Sheet2
D21: AY 2018-19 | F21: AY 2019-20 | H21: AY 2020-21 | J21: AY 2021-22 | L21: AY 2022-23 | N21: AY 2023-24 | P21: AY 2024-25
D22: M18 | E22: S19 | F22: M19 | G22: S20 | H22: M20 | I22: S21 | J22: M21 | K22: S22 | L22: M22 | M22: S23 | N22: M24 | O22: S24 | P22: M25 | Q22: S25

Sheet Weights and Confidence
D13: 1 | E13: 2 | F13: 3 | G13: =F13+1 -> 4 | H13: =G13+1 -> 5 | I13: =H13+1 -> 6 | J13: =I13+1 -> 7 | K13: =J13+1 -> 8 | L13: =K13+1 -> 9 | M13: =L13+1 -> 10 | N13: =M13+1 -> 11 | ... AC13: =AB13+1 -> 26
D14: Weights and Cinfidence Factors
F15: M18 | H15: S 19 | J15: M19 | L15: S20 | N15: M20 | P15: S21 | R15: M21 | T15: S22 | V15: M23 | X15: S24 | Z15: M24 | AB15: S25
D16: C1 | E16: Brief/problem specification & learning outcomes clarity | F16: 0.12 | G16: 1 | H16: 0.12 | I16: 1 | J16: 0.12 | K16: 1 | L16: 0.12 | M16: 1 | N16: 0.12 | O16: 1 | P16: 0.12 | Q16: 1 | R16: 0.12 | S16: 1 | T16: 0.12 | U16: 1 | V16: 0.12 | W16: 1 | X16: 0.12 | Y16: 1 | Z16: 0.12 | AA16: 1 | AB16: 0.12 | AC16: 1
D17: C2 | E17: Studio structure: exercises aligned to outcomes / ability focus | F17: 0.08 | G17: 0.8 | H17: 0.08 | I17: 0.8 | J17: 0.08 | K17: 0.8 | L17: 0.08 | M17: 0.8 | N17: 0.08 | O17: 0.9 | P17: 0.08 | Q17: 0.9 | R17: 0.08 | S17: 0.9 | T17: 0.08 | U17: 1 | V17: 0.08 | W17: 1 | X17: 0.08 | Y17: 1 | Z17: 0.08 | AA17: 1 | AB17: 0.08 | AC17: 1
D18: C3 | E18: Exploration latitude: not too narrow / not too broad | F18: 0.05 | G18: 1 | H18: 0.05 | I18: 1 | J18: 0.05 | K18: 1 | L18: 0.05 | M18: 1 | N18: 0.05 | O18: 1 | P18: 0.05 | Q18: 1 | R18: 0.05 | S18: 1 | T18: 0.05 | U18: 1 | V18: 0.05 | W18: 1 | X18: 0.05 | Y18: 1 | Z18: 0.05 | AA18: 1 | AB18: 0.05 | AC18: 1
D19: C4 | E19: Student engagement & grappling intensity | F19: 0.14 | G19: 1 | H19: 0.14 | I19: 1 | J19: 0.14 | K19: 1 | L19: 0.14 | M19: 1 | N19: 0.1 | O19: 1 | P19: 0.1 | Q19: 1 | R19: 0.1 | S19: 1 | T19: 0.1 | U19: 1 | V19: 0.1 | W19: 1 | X19: 0.1 | Y19: 1 | Z19: 0.1 | AA19: 1 | AB19: 0.1 | AC19: 1
D20: C5 | E20: Depth of understanding & conceptual clarity | F20: 0 | G20: 0 | H20: 0 | I20: 0 | J20: 0 | K20: 0 | L20: 0 | M20: 0 | N20: 0.08 | O20: 1 | P20: 0.08 | Q20: 1 | R20: 0.08 | S20: 1 | T20: 0.08 | U20: 1 | V20: 0.08 | W20: 1 | X20: 0.08 | Y20: 1 | Z20: 0.08 | AA20: 1 | AB20: 0.08 | AC20: 1
D21: C6 | E21: Ability achievement: outcomes attained in work | F21: 0.11 | G21: 1 | H21: 0.11 | I21: 1 | J21: 0.11 | K21: 1 | L21: 0.11 | M21: 1 | N21: 0.07 | O21: 1 | P21: 0.07 | Q21: 1 | R21: 0.07 | S21: 1 | T21: 0.07 | U21: 1 | V21: 0.07 | W21: 1 | X21: 0.07 | Y21: 1 | Z21: 0.07 | AA21: 1 | AB21: 0.07 | AC21: 1
D22: C7 | E22: Architectural quality / convincing proposals | F22: 0.15 | G22: 1 | H22: 0.15 | I22: 1 | J22: 0.15 | K22: 1 | L22: 0.15 | M22: 1 | N22: 0.15 | O22: 1 | P22: 0.15 | Q22: 1 | R22: 0.15 | S22: 1 | T22: 0.15 | U22: 1 | V22: 0.15 | W22: 1 | X22: 0.15 | Y22: 1 | Z22: 0.15 | AA22: 1 | AB22: 0.15 | AC22: 1
D23: C8 | E23: Rigor, resolution & care | F23: 0.1 | G23: 1 | H23: 0.1 | I23: 1 | J23: 0.1 | K23: 1 | L23: 0.1 | M23: 1 | N23: 0.1 | O23: 1 | P23: 0.1 | Q23: 1 | R23: 0.1 | S23: 1 | T23: 0.1 | U23: 1 | V23: 0.1 | W23: 1 | X23: 0.1 | Y23: 1 | Z23: 0.1 | AA23: 1 | AB23: 0.1 | AC23: 1
D24: C9 | E24: Workmanship / visual representation quality | F24: 0.1 | G24: 1 | H24: 0.1 | I24: 1 | J24: 0.1 | K24: 1 | L24: 0.1 | M24: 1 | N24: 0.1 | O24: 1 | P24: 0.1 | Q24: 1 | R24: 0.1 | S24: 1 | T24: 0.1 | U24: 1 | V24: 0.1 | W24: 1 | X24: 0.1 | Y24: 1 | Z24: 0.1 | AA24: 1 | AB24: 0.1 | AC24: 1
D25: C10 | E25: Communication: presentation / exhibition / portfolio clarity | F25: 0.1 | G25: 0.85 | H25: 0.1 | I25: 0.85 | J25: 0.1 | K25: 0.85 | L25: 0.1 | M25: 0.85 | N25: 0.1 | O25: 0.9 | P25: 0.1 | Q25: 0.9 | R25: 0.1 | S25: 0.9 | T25: 0.1 | U25: 1 | V25: 0.1 | W25: 1 | X25: 0.1 | Y25: 1 | Z25: 0.1 | AA25: 1 | AB25: 0.1 | AC25: 1
D26: C11 | E26: International benchmarking / parity | F26: 0.05 | G26: 1 | H26: 0.05 | I26: 1 | J26: 0.05 | K26: 1 | L26: 0.05 | M26: 1 | N26: 0.05 | O26: 1 | P26: 0.05 | Q26: 1 | R26: 0.05 | S26: 1 | T26: 0.05 | U26: 1 | V26: 0.05 | W26: 1 | X26: 0.05 | Y26: 1 | Z26: 0.05 | AA26: 1 | AB26: 0.05 | AC26: 1

Sheet Sheet12
A2: Semester | B2: M18
A4: Sum of Final_Score | B4: Column Labels
A5: Row Labels | B5: P1 | C5: P2 | D5: Grand Total
A6: AR2001 | B6: 9 | C6: 10 | D6: 19
A7: AR2004 | B7: 3 | C7: 10 | D7: 13
A8: AR2005 | B8: 8 | C8: 9 | D8: 17
A9: AR2010 | B9: 1 | C9: 4 | D9: 5
A10: AR2011 | B10: 9 | C10: 10 | D10: 19
A11: AR2012 | B11: 11 | C11: 8 | D11: 19
A12: AR2013 | B12: -6 | C12: 5 | D12: -1
A13: AR2014 | B13: 11 | C13: 11 | D13: 22
A14: AR2015 | B14: -5 | C14: -5 | D14: -10
A15: AR2016 | B15: 11 | C15: 11 | D15: 22
A16: AR2017 | B16: 0 | C16: -4 | D16: -4
A17: AR3001 | B17: -3 | C17: -7 | D17: -10
A18: AR3002 | B18: 6 | C18: 1 | D18: 7 | G18: Semester | H18: M18 | L18: Semester | M18: M18
A19: AR3003 | B19: -4 | C19: -8 | D19: -12
A20: AR3004 | B20: 5 | C20: 7 | D20: 12 | G20: Sum of Final_Score | H20: Column Labels | L20: Sum of Final_Score | M20: Column Labels
A21: AR3005 | B21: -5 | C21: -1 | D21: -6 | H21: P1 | I21: P2 | J21: Grand Total | M21: P1 | N21: P2 | O21: Grand Total
A22: Grand Total | B22: 51 | C22: 61 | D22: 112 | G22: AR2001 | H22: 9 | I22: 10 | J22: 19 | K22: =J22/2 -> 9.5 | L22: AR2001 | M22: 0.7865 | N22: 0.919 | O22: 1.7055 | P22: =O22/2 -> 0.85275 | Q22: =P22*10 -> 8.5275
G23: AR2004 | H23: 3 | I23: 10 | J23: 13 | K23: =J23/2 -> 6.5 | L23: AR2004 | M23: 0.234 | N23: 0.919 | O23: 1.153 | P23: =O23/2 -> 0.5765 | Q23: =P23*10 -> 5.765
G24: AR2005 | H24: 8 | I24: 9 | J24: 17 | K24: =J24/2 -> 8.5 | L24: AR2005 | M24: 0.679 | N24: 0.819 | O24: 1.498 | P24: =O24/2 -> 0.749 | Q24: =P24*10 -> 7.49
G25: AR2010 | H25: 1 | I25: 4 | J25: 5 | K25: =J25/2 -> 2.5 | L25: AR2010 | M25: -0.125 | N25: 0.369 | O25: 0.244 | P25: =O25/2 -> 0.122 | Q25: =P25*10 -> 1.22
G26: AR2011 | H26: 9 | I26: 10 | J26: 19 | K26: =J26/2 -> 9.5 | L26: AR2011 | M26: 0.779 | N26: 0.919 | O26: 1.698 | P26: =O26/2 -> 0.849 | Q26: =P26*10 -> 8.49
G27: AR2012 | H27: 11 | I27: 8 | J27: 19 | K27: =J27/2 -> 9.5 | L27: AR2012 | M27: 0.969 | N27: 0.709 | O27: 1.678 | P27: =O27/2 -> 0.839 | Q27: =P27*10 -> 8.39
G28: AR2013 | H28: -6 | I28: 5 | J28: -1 | K28: =J28/2 -> -0.5 | L28: AR2013 | M28: -0.5565 | N28: 0.4665 | O28: -0.09 | P28: =O28/2 -> -0.045 | Q28: =P28*10 -> -0.45
G29: AR2014 | H29: 11 | I29: 11 | J29: 22 | K29: =J29/2 -> 11 | L29: AR2014 | M29: 0.969 | N29: 0.969 | O29: 1.938 | P29: =O29/2 -> 0.969 | Q29: =P29*10 -> 9.69
G30: AR2015 | H30: -5 | I30: -5 | J30: -10 | K30: =J30/2 -> -5 | L30: AR2015 | M30: -0.54 | N30: -0.48 | O30: -1.02 | P30: =O30/2 -> -0.51 | Q30: =P30*10 -> -5.1
G31: AR2016 | H31: 11 | I31: 11 | J31: 22 | K31: =J31/2 -> 11 | L31: AR2016 | M31: 0.969 | N31: 0.969 | O31: 1.938 | P31: =O31/2 -> 0.969 | Q31: =P31*10 -> 9.69
G32: AR2017 | H32: 0 | I32: -4 | J32: -4 | K32: =J32/2 -> -2 | L32: AR2017 | M32: 0.1575 | N32: -0.3325 | O32: -0.175 | P32: =O32/2 -> -0.0875 | Q32: =P32*10 -> -0.875
G33: AR3001 | H33: -3 | I33: -7 | J33: -10 | K33: =J33/2 -> -5 | L33: AR3001 | M33: -0.2925 | N33: -0.6925 | O33: -0.985 | P33: =O33/2 -> -0.4925 | Q33: =P33*10 -> -4.925
G34: AR3002 | H34: 6 | I34: 1 | J34: 7 | K34: =J34/2 -> 3.5 | L34: AR3002 | M34: 0.57 | N34: -0.055 | O34: 0.515 | P34: =O34/2 -> 0.2575 | Q34: =P34*10 -> 2.575
G35: AR3003 | H35: -4 | I35: -8 | J35: -12 | K35: =J35/2 -> -6 | L35: AR3003 | M35: -0.52 | N35: -0.735 | P35: =O35/2 -> 0 | Q35: =P35*10 -> 0
G36: AR3004 | H36: 5 | I36: 7 | J36: 12 | K36: =J36/2 -> 6 | L36: AR3004 | M36: 0.335 | N36: 0.669 | O36: 1.004 | P36: =O36/2 -> 0.502 | Q36: =P36*10 -> 5.02
G37: AR3005 | H37: -5 | I37: -1 | J37: -6 | K37: =J37/2 -> -3 | L37: AR3005 | M37: -0.415 | N37: -0.066 | O37: -0.481 | P37: =O37/2 -> -0.2405 | Q37: =P37*10 -> -2.405
G38: Grand Total | H38: 51 | I38: 61 | J38: 112 | K38: =J38/2 -> 56 | L38: Grand Total | M38: 3.999 | N38: 5.3665 | O38: 9.3655 | P38: =O38/2 -> 4.68275
H39: =SUM(H22:H37) -> 51 | I39: =SUM(I22:I37) -> 61 | J39: =SUM(J22:J37) -> 112 | M39: =SUM(M22:M37) -> 3.999 | N39: =SUM(N22:N37) -> 5.3665 | O39: =SUM(O22:O37) -> 10.6205 | P39: =SUM(P22:P37) -> 5.31025 | Q39: =SUM(Q22:Q37) -> 53.1025

Sheet Normalized Score (2)
A5: AY | B5: Semester | C5: Studio_Code | D5: Level | E5: Studio_Focus_Area | F5: Studio_Title | G5: Question_No | H5: Panel_ID | I5: Construct_ID | J5: Raw_Rating_Text | K5: Weight | L5: Confidence | M5: Final_Score | N5: Notes
A6: 2018-19 | B6: M18 | C6: AR2001 | D6: L2 | E6: Visualization and Communication | F6: The Purpose of Architecture: Exploring Design Interventions and Strategies | G6: 1 | H6: P1 | I6: C1 | J6: 1 | K6: =VLOOKUP(I6,'Weights and Confidence'!$D$16:$AC$26,5,FALSE)/COUNTIFS($B:$B,$B6,$C:$C,$C6,$H:$H,$H6,$I:$I,$I6) -> 0.12 | L6: =VLOOKUP(I6,'Weights and Confidence'!$D$16:$AC$26,6,FALSE) -> 1 | M6: =tScores4[[#This Row],[Raw_Rating_Text]] -> 1 | O6: =tScores4[[#This Row],[Raw_Rating_Text]]+J8+J10+J12+J14+J16+J18+J20+J22+J24+J26 -> 9
A7: 2018-19 | B7: M18 | C7: AR2001 | D7: L2 | E7: Visualization and Communication | F7: The Purpose of Architecture: Exploring Design Interventions and Strategies | G7: 1 | H7: P2 | I7: C1 | J7: 1 | K7: =VLOOKUP(I7,'Weights and Confidence'!$D$16:$AC$26,5,FALSE)/COUNTIFS($B:$B,$B7,$C:$C,$C7,$H:$H,$H7,$I:$I,$I7) -> 0.12 | L7: =VLOOKUP(I7,'Weights and Confidence'!$D$16:$AC$26,6,FALSE) -> 1 | M7: =tScores4[[#This Row],[Raw_Rating_Text]] -> 1 | O7: =tScores4[[#This Row],[Raw_Rating_Text]]+J9+J11+J13+J15+J17+J19+J21+J23+J25+J27 -> 10
A8: 2018-19 | B8: M18 | C8: AR2001 | D8: L2 | E8: Visualization and Communication | F8: The Purpose of Architecture: Exploring Design Interventions and Strategies | G8: 2 | H8: P1 | I8: C2 | J8: 1 | K8: =VLOOKUP(I8,'Weights and Confidence'!$D$16:$AC$26,5,FALSE)/COUNTIFS($B:$B,$B8,$C:$C,$C8,$H:$H,$H8,$I:$I,$I8) -> 0.08 | L8: =VLOOKUP(I8,'Weights and Confidence'!$D$16:$AC$26,6,FALSE) -> 0.8 | M8: =tScores4[[#This Row],[Raw_Rating_Text]] -> 1
A9: 2018-19 | B9: M18 | C9: AR2001 | D9: L2 | E9: Visualization and Communication | F9: The Purpose of Architecture: Exploring Design Interventions and Strategies | G9: 2 | H9: P2 | I9: C2 | J9: 1 | K9: =VLOOKUP(I9,'Weights and Confidence'!$D$16:$AC$26,5,FALSE)/COUNTIFS($B:$B,$B9,$C:$C,$C9,$H:$H,$H9,$I:$I,$I9) -> 0.08 | L9: =VLOOKUP(I9,'Weights and Confidence'!$D$16:$AC$26,6,FALSE) -> 0.8 | M9: =tScores4[[#This Row],[Raw_Rating_Text]] -> 1
A10: 2018-19 | B10: M18 | C10: AR2001 | D10: L2 | E10: Visualization and Communication | F10: The Purpose of Architecture: Exploring Design Interventions and Strategies | G10: 3 | H10: P1 | I10: C3 | J10: 1 | K10: =VLOOKUP(I10,'Weights and Confidence'!$D$16:$AC$26,5,FALSE)/COUNTIFS($B:$B,$B10,$C:$C,$C10,$H:$H,$H10,$I:$I,$I10) -> 0.05 | L10: =VLOOKUP(I10,'Weights and Confidence'!$D$16:$AC$26,6,FALSE) -> 1 | M10: =tScores4[[#This Row],[Raw_Rating_Text]] -> 1
A11: 2018-19 | B11: M18 | C11: AR2001 | D11: L2 | E11: Visualization and Communication | F11: The Purpose of Architecture: Exploring Design Interventions and Strategies | G11: 3 | H11: P2 | I11: C3 | J11: 1 | K11: =VLOOKUP(I11,'Weights and Confidence'!$D$16:$AC$26,5,FALSE)/COUNTIFS($B:$B,$B11,$C:$C,$C11,$H:$H,$H11,$I:$I,$I11) -> 0.05 | L11: =VLOOKUP(I11,'Weights and Confidence'!$D$16:$AC$26,6,FALSE) -> 1 | M11: =tScores4[[#This Row],[Raw_Rating_Text]] -> 1
A12: 2018-19 | B12: M18 | C12: AR2001 | D12: L2 | E12: Visualization and Communication | F12: The Purpose of Architecture: Exploring Design Interventions and Strategies | G12: 4 | H12: P1 | I12: C4 | J12: 0 | K12: =VLOOKUP(I12,'Weights and Confidence'!$D$16:$AC$26,5,FALSE)/COUNTIFS($B:$B,$B12,$C:$C,$C12,$H:$H,$H12,$I:$I,$I12) -> 0.14 | L12: =VLOOKUP(I12,'Weights and Confidence'!$D$16:$AC$26,6,FALSE) -> 1 | M12: =tScores4[[#This Row],[Raw_Rating_Text]] -> 0
A13: 2018-19 | B13: M18 | C13: AR2001 | D13: L2 | E13: Visualization and Communication | F13: The Purpose of Architecture: Exploring Design Interventions and Strategies | G13: 4 | H13: P2 | I13: C4 | J13: 1 | K13: =VLOOKUP(I13,'Weights and Confidence'!$D$16:$AC$26,5,FALSE)/COUNTIFS($B:$B,$B13,$C:$C,$C13,$H:$H,$H13,$I:$I,$I13) -> 0.14 | L13: =VLOOKUP(I13,'Weights and Confidence'!$D$16:$AC$26,6,FALSE) -> 1 | M13: =tScores4[[#This Row],[Raw_Rating_Text]] -> 1
A14: 2018-19 | B14: M18 | C14: AR2001 | D14: L2 | E14: Visualization and Communication | F14: The Purpose of Architecture: Exploring Design Interventions and Strategies | G14: 5 | H14: P1 | I14: C6 | J14: 1 | K14: =VLOOKUP(I14,'Weights and Confidence'!$D$16:$AC$26,5,FALSE)/COUNTIFS($B:$B,$B14,$C:$C,$C14,$H:$H,$H14,$I:$I,$I14) -> 0.11 | L14: =VLOOKUP(I14,'Weights and Confidence'!$D$16:$AC$26,6,FALSE) -> 1 | M14: =tScores4[[#This Row],[Raw_Rating_Text]] -> 1
A15: 2018-19 | B15: M18 | C15: AR2001 | D15: L2 | E15: Visualization and Communication | F15: The Purpose of Architecture: Exploring Design Interventions and Strategies | G15: 5 | H15: P2 | I15: C6 | J15: 1 | K15: =VLOOKUP(I15,'Weights and Confidence'!$D$16:$AC$26,5,FALSE)/COUNTIFS($B:$B,$B15,$C:$C,$C15,$H:$H,$H15,$I:$I,$I15) -> 0.11 | L15: =VLOOKUP(I15,'Weights and Confidence'!$D$16:$AC$26,6,FALSE) -> 1 | M15: =tScores4[[#This Row],[Raw_Rating_Text]] -> 1
A16: 2018-19 | B16: M18 | C16: AR2001 | D16: L2 | E16: Visualization and Communication | F16: The Purpose of Architecture: Exploring Design Interventions and Strategies | G16: 6 | H16: P1 | I16: C7 | J16: 1 | K16: =VLOOKUP(I16,'Weights and Confidence'!$D$16:$AC$26,5,FALSE)/COUNTIFS($B:$B,$B16,$C:$C,$C16,$H:$H,$H16,$I:$I,$I16) -> 0.15 | L16: =VLOOKUP(I16,'Weights and Confidence'!$D$16:$AC$26,6,FALSE) -> 1 | M16: =tScores4[[#This Row],[Raw_Rating_Text]] -> 1
A17: 2018-19 | B17: M18 | C17: AR2001 | D17: L2 | E17: Visualization and Communication | F17: The Purpose of Architecture: Exploring Design Interventions and Strategies | G17: 6 | H17: P2 | I17: C7 | J17: 1 | K17: =VLOOKUP(I17,'Weights and Confidence'!$D$16:$AC$26,5,FALSE)/COUNTIFS($B:$B,$B17,$C:$C,$C17,$H:$H,$H17,$I:$I,$I17) -> 0.15 | L17: =VLOOKUP(I17,'Weights and Confidence'!$D$16:$AC$26,6,FALSE) -> 1 | M17: =tScores4[[#This Row],[Raw_Rating_Text]] -> 1
A18: 2018-19 | B18: M18 | C18: AR2001 | D18: L2 | E18: Visualization and Communication | F18: The Purpose of Architecture: Exploring Design Interventions and Strategies | G18: 7 | H18: P1 | I18: C8 | J18: 1 | K18: =VLOOKUP(I18,'Weights and Confidence'!$D$16:$AC$26,5,FALSE)/COUNTIFS($B:$B,$B18,$C:$C,$C18,$H:$H,$H18,$I:$I,$I18) -> 0.1 | L18: =VLOOKUP(I18,'Weights and Confidence'!$D$16:$AC$26,6,FALSE) -> 1 | M18: =tScores4[[#This Row],[Raw_Rating_Text]] -> 1
A19: 2018-19 | B19: M18 | C19: AR2001 | D19: L2 | E19: Visualization and Communication | F19: The Purpose of Architecture: Exploring Design Interventions and Strategies | G19: 7 | H19: P2 | I19: C8 | J19: 1 | K19: =VLOOKUP(I19,'Weights and Confidence'!$D$16:$AC$26,5,FALSE)/COUNTIFS($B:$B,$B19,$C:$C,$C19,$H:$H,$H19,$I:$I,$I19) -> 0.1 | L19: =VLOOKUP(I19,'Weights and Confidence'!$D$16:$AC$26,6,FALSE) -> 1 | M19: =tScores4[[#This Row],[Raw_Rating_Text]] -> 1
... A27: 2018-19 | B27: M18 | C27: AR2001 | D27: L2 | E27: Visualization and Communication | F27: The Purpose of Architecture: Exploring Design Interventions and Strategies | G27: 11 | H27: P2 | I27: C11 | J27: 0 | K27: =VLOOKUP(I27,'Weights and Confidence'!$D$16:$AC$26,5,FALSE)/COUNTIFS($B:$B,$B27,$C:$C,$C27,$H:$H,$H27,$I:$I,$I27) -> 0.05 | L27: =VLOOKUP(I27,'Weights and Confidence'!$D$16:$AC$26,6,FALSE) -> 1 | M27: =tScores4[[#This Row],[Raw_Rating_Text]] -> 0
A28: 2018-19 | B28: M18 | C28: AR2004 | D28: L2 | E28: Constructing and Specifying | F28: Strange Details | G28: 1 | H28: P1 | I28: C1 | J28: 1 | K28: =VLOOKUP(I28,'Weights and Confidence'!$D$16:$AC$26,5,FALSE)/COUNTIFS($B:$B,$B28,$C:$C,$C28,$H:$H,$H28,$I:$I,$I28) -> 0.12 | L28: =VLOOKUP(I28,'Weights and Confidence'!$D$16:$AC$26,6,FALSE) -> 1 | M28: =tScores4[[#This Row],[Raw_Rating_Text]] -> 1 | O28: =tScores4[[#This Row],[Raw_Rating_Text]]+J30+J32+J34+J36+J38+J40+J42+J44+J46+J48 -> 3
A29: 2018-19 | B29: M18 | C29: AR2004 | D29: L2 | E29: Constructing and Specifying | F29: Strange Details | G29: 1 | H29: P2 | I29: C1 | J29: 1 | K29: =VLOOKUP(I29,'Weights and Confidence'!$D$16:$AC$26,5,FALSE)/COUNTIFS($B:$B,$B29,$C:$C,$C29,$H:$H,$H29,$I:$I,$I29) -> 0.12 | L29: =VLOOKUP(I29,'Weights and Confidence'!$D$16:$AC$26,6,FALSE) -> 1 | M29: =tScores4[[#This Row],[Raw_Rating_Text]] -> 1 | O29: =tScores4[[#This Row],[Raw_Rating_Text]]+J31+J33+J35+J37+J39+J41+J43+J45+J47+J49 -> 10
A30: 2018-19 | B30: M18 | C30: AR2004 | D30: L2 | E30: Constructing and Specifying | F30: Strange Details | G30: 2 | H30: P1 | I30: C2 | J30: 1 | K30: =VLOOKUP(I30,'Weights and Confidence'!$D$16:$AC$26,5,FALSE)/COUNTIFS($B:$B,$B30,$C:$C,$C30,$H:$H,$H30,$I:$I,$I30) -> 0.08 | L30: =VLOOKUP(I30,'Weights and Confidence'!$D$16:$AC$26,6,FALSE) -> 0.8 | M30: =tScores4[[#This Row],[Raw_Rating_Text]] -> 1
A31: 2018-19 | B31: M18 | C31: AR2004 | D31: L2 | E31: Constructing and Specifying | F31: Strange Details | G31: 2 | H31: P2 | I31: C2 | J31: 1 | K31: =VLOOKUP(I31,'Weights and Confidence'!$D$16:$AC$26,5,FALSE)/COUNTIFS($B:$B,$B31,$C:$C,$C31,$H:$H,$H31,$I:$I,$I31) -> 0.08 | L31: =VLOOKUP(I31,'Weights and Confidence'!$D$16:$AC$26,6,FALSE) -> 0.8 | M31: =tScores4[[#This Row],[Raw_Rating_Text]] -> 1
A32: 2018-19 | B32: M18 | C32: AR2004 | D32: L2 | E32: Constructing and Specifying | F32: Strange Details | G32: 3 | H32: P1 | I32: C3 | J32: 1 | K32: =VLOOKUP(I32,'Weights and Confidence'!$D$16:$AC$26,5,FALSE)/COUNTIFS($B:$B,$B32,$C:$C,$C32,$H:$H,$H32,$I:$I,$I32) -> 0.05 | L32: =VLOOKUP(I32,'Weights and Confidence'!$D$16:$AC$26,6,FALSE) -> 1 | M32: =tScores4[[#This Row],[Raw_Rating_Text]] -> 1
A33: 2018-19 | B33: M18 | C33: AR2004 | D33: L2 | E33: Constructing and Specifying | F33: Strange Details | G33: 3 | H33: P2 | I33: C3 | J33: 1 | K33: =VLOOKUP(I33,'Weights and Confidence'!$D$16:$AC$26,5,FALSE)/COUNTIFS($B:$B,$B33,$C:$C,$C33,$H:$H,$H33,$I:$I,$I33) -> 0.05 | L33: =VLOOKUP(I33,'Weights and Confidence'!$D$16:$AC$26,6,FALSE) -> 1 | M33: =tScores4[[#This Row],[Raw_Rating_Text]] -> 1
A34: 2018-19 | B34: M18 | C34: AR2004 | D34: L2 | E34: Constructing and Specifying | F34: Strange Details | G34: 4 | H34: P1 | I34: C4 | J34: 0 | K34: =VLOOKUP(I34,'Weights and Confidence'!$D$16:$AC$26,5,FALSE)/COUNTIFS($B:$B,$B34,$C:$C,$C34,$H:$H,$H34,$I:$I,$I34) -> 0.14 | L34: =VLOOKUP(I34,'Weights and Confidence'!$D$16:$AC$26,6,FALSE) -> 1 | M34: =tScores4[[#This Row],[Raw_Rating_Text]] -> 0
A35: 2018-19 | B35: M18 | C35: AR2004 | D35: L2 | E35: Constructing and Specifying | F35: Strange Details | G35: 4 | H35: P2 | I35: C4 | J35: 1 | K35: =VLOOKUP(I35,'Weights and Confidence'!$D$16:$AC$26,5,FALSE)/COUNTIFS($B:$B,$B35,$C:$C,$C35,$H:$H,$H35,$I:$I,$I35) -> 0.14 | L35: =VLOOKUP(I35,'Weights and Confidence'!$D$16:$AC$26,6,FALSE) -> 1 | M35: =tScores4[[#This Row],[Raw_Rating_Text]] -> 1
A36: 2018-19 | B36: M18 | C36: AR2004 | D36: L2 | E36: Constructing and Specifying | F36: Strange Details | G36: 5 | H36: P1 | I36: C6 | J36: 0 | K36: =VLOOKUP(I36,'Weights and Confidence'!$D$16:$AC$26,5,FALSE)/COUNTIFS($B:$B,$B36,$C:$C,$C36,$H:$H,$H36,$I:$I,$I36) -> 0.11 | L36: =VLOOKUP(I36,'Weights and Confidence'!$D$16:$AC$26,6,FALSE) -> 1 | M36: =tScores4[[#This Row],[Raw_Rating_Text]] -> 0
A37: 2018-19 | B37: M18 | C37: AR2004 | D37: L2 | E37: Constructing and Specifying | F37: Strange Details | G37: 5 | H37: P2 | I37: C6 | J37: 1 | K37: =VLOOKUP(I37,'Weights and Confidence'!$D$16:$AC$26,5,FALSE)/COUNTIFS($B:$B,$B37,$C:$C,$C37,$H:$H,$H37,$I:$I,$I37) -> 0.11 | L37: =VLOOKUP(I37,'Weights and Confidence'!$D$16:$AC$26,6,FALSE) -> 1 | M37: =tScores4[[#This Row],[Raw_Rating_Text]] -> 1
A38: 2018-19 | B38: M18 | C38: AR2004 | D38: L2 | E38: Constructing and Specifying | F38: Strange Details | G38: 6 | H38: P1 | I38: C7 | J38: 0 | K38: =VLOOKUP(I38,'Weights and Confidence'!$D$16:$AC$26,5,FALSE)/COUNTIFS($B:$B,$B38,$C:$C,$C38,$H:$H,$H38,$I:$I,$I38) -> 0.15 | L38: =VLOOKUP(I38,'Weights and Confidence'!$D$16:$AC$26,6,FALSE) -> 1 | M38: =tScores4[[#This Row],[Raw_Rating_Text]] -> 0
A39: 2018-19 | B39: M18 | C39: AR2004 | D39: L2 | E39: Constructing and Specifying | F39: Strange Details | G39: 6 | H39: P2 | I39: C7 | J39: 1 | K39: =VLOOKUP(I39,'Weights and Confidence'!$D$16:$AC$26,5,FALSE)/COUNTIFS($B:$B,$B39,$C:$C,$C39,$H:$H,$H39,$I:$I,$I39) -> 0.15 | L39: =VLOOKUP(I39,'Weights and Confidence'!$D$16:$AC$26,6,FALSE) -> 1 | M39: =tScores4[[#This Row],[Raw_Rating_Text]] -> 1
A40: 2018-19 | B40: M18 | C40: AR2004 | D40: L2 | E40: Constructing and Specifying | F40: Strange Details | G40: 7 | H40: P1 | I40: C8 | J40: 0 | K40: =VLOOKUP(I40,'Weights and Confidence'!$D$16:$AC$26,5,FALSE)/COUNTIFS($B:$B,$B40,$C:$C,$C40,$H:$H,$H40,$I:$I,$I40) -> 0.1 | L40: =VLOOKUP(I40,'Weights and Confidence'!$D$16:$AC$26,6,FALSE) -> 1 | M40: =tScores4[[#This Row],[Raw_Rating_Text]] -> 0
A41: 2018-19 | B41: M18 | C41: AR2004 | D41: L2 | E41: Constructing and Specifying | F41: Strange Details | G41: 7 | H41: P2 | I41: C8 | J41: 1 | K41: =VLOOKUP(I41,'Weights and Confidence'!$D$16:$AC$26,5,FALSE)/COUNTIFS($B:$B,$B41,$C:$C,$C41,$H:$H,$H41,$I:$I,$I41) -> 0.1 | L41: =VLOOKUP(I41,'Weights and Confidence'!$D$16:$AC$26,6,FALSE) -> 1 | M41: =tScores4[[#This Row],[Raw_Rating_Text]] -> 1
... A49: 2018-19 | B49: M18 | C49: AR2004 | D49: L2 | E49: Constructing and Specifying | F49: Strange Details | G49: 11 | H49: P2 | I49: C11 | J49: 0 | K49: =VLOOKUP(I49,'Weights and Confidence'!$D$16:$AC$26,5,FALSE)/COUNTIFS($B:$B,$B49,$C:$C,$C49,$H:$H,$H49,$I:$I,$I49) -> 0.05 | L49: =VLOOKUP(I49,'Weights and Confidence'!$D$16:$AC$26,6,FALSE) -> 1 | M49: =tScores4[[#This Row],[Raw_Rating_Text]] -> 0
A50: 2018-19 | B50: M18 | C50: AR2005 | D50: L2 | E50: Spatial Planning and Organization | F50: Of Immediate and Afar | G50: 1 | H50: P1 | I50: C1 | J50: 1 | K50: =VLOOKUP(I50,'Weights and Confidence'!$D$16:$AC$26,5,FALSE)/COUNTIFS($B:$B,$B50,$C:$C,$C50,$H:$H,$H50,$I:$I,$I50) -> 0.12 | L50: =VLOOKUP(I50,'Weights and Confidence'!$D$16:$AC$26,6,FALSE) -> 1 | M50: =tScores4[[#This Row],[Raw_Rating_Text]] -> 1 | O50: =tScores4[[#This Row],[Raw_Rating_Text]]+J52+J54+J56+J58+J60+J62+J64+J66+J68+J70 -> 8 | P50: ='Normalized Score (2)'!$M50+M52+M54+M56+M58+M60+M62+M64+M66+M68+M70 -> 8
A51: 2018-19 | B51: M18 | C51: AR2005 | D51: L2 | E51: Spatial Planning and Organization | F51: Of Immediate and Afar | G51: 1 | H51: P2 | I51: C1 | J51: 1 | K51: =VLOOKUP(I51,'Weights and Confidence'!$D$16:$AC$26,5,FALSE)/COUNTIFS($B:$B,$B51,$C:$C,$C51,$H:$H,$H51,$I:$I,$I51) -> 0.12 | L51: =VLOOKUP(I51,'Weights and Confidence'!$D$16:$AC$26,6,FALSE) -> 1 | M51: =tScores4[[#This Row],[Raw_Rating_Text]] -> 1 | O51: =tScores4[[#This Row],[Raw_Rating_Text]]+J53+J55+J57+J59+J61+J63+J65+J67+J69+J71 -> 9
A52: 2018-19 | B52: M18 | C52: AR2005 | D52: L2 | E52: Spatial Planning and Organization | F52: Of Immediate and Afar | G52: 2 | H52: P1 | I52: C2 | J52: 1 | K52: =VLOOKUP(I52,'Weights and Confidence'!$D$16:$AC$26,5,FALSE)/COUNTIFS($B:$B,$B52,$C:$C,$C52,$H:$H,$H52,$I:$I,$I52) -> 0.08 | L52: =VLOOKUP(I52,'Weights and Confidence'!$D$16:$AC$26,6,FALSE) -> 0.8 | M52: =tScores4[[#This Row],[Raw_Rating_Text]] -> 1
